Workbook
Name A: #REF!
Name A: #REF!
Name A: #REF!
Name A: #REF!
Name BMM: #REF!
Name BMM: #REF!
Name BMM: #REF!
Name BMM: #REF!
Name idhoi: #REF!
Name idhoi: #REF!
Name idhoi: #REF!
Name idhoi: #REF!
Name QQP: 'Catálogo SAP'!$D$2:$F$41
Name QQP: #REF!
Name qqqq: #REF!
Name qqqq: #REF!
Name qqqq: #REF!
Name qqqq: #REF!
Name TURMA: #REF!
Name TURMA: #REF!
Name TURMA: #REF!
Name TURMA: #REF!
Name w: #REF!
Name w: #REF!
Name w: #REF!
Name w: #REF!

Sheet Catálogo SAP
A1: RENTAL - Item | B1: Código do Item | C1: RENTAL - CÓDIGO SAP | D1: RENTAL - Descrição | E1: RENTAL - Und. | F1: RENTAL - Preço | G1: MOBRA - CÓDIGO SAP | H1: MOBRA - Descrição | I1: MOBRA - Und. | J1: MOBRA - Preço | K1: Tipo do Serviço | L1: Tipo do Equipamento
A2: 100 | B2: 100 | C2: S.VP-01435 | D2: Mobilização De Retroescavadeira C/ Operador | E2: VB | F2: 1569.45 | G2: S.VP-01477 | H2: MOBILIZAÇÃO DE RETROESCAVADEIRA C/ OPERADOR | I2: VB | J2: 963.41417 | K2: Mobilização | L2: Retroescavadeira
A3: 110 | B3: 110 | C3: S.VP-01436 | D3: Desmobilização De Retroescavadeira C/ Operador | E3: VB | F3: 1569.45 | G3: S.VP-01478 | H3: DESMOBILIZAÇÃO DE RETROESCAVADEIRA C/ OPERADOR | I3: VB | J3: 963.41417 | K3: Desmobilização | L3: Retroescavadeira
A4: 120 | B4: 120 | C4: S.VP-01437 | D4: Hr Produtiva Retroescavadeira C/Operador | E4: H | F4: 160.71 | G4: S.VP-01395 | H4: HR PRODUTIVA RETROESCAVADEIRA C/OPERADOR | I4: H | J4: 65.42 | K4: Produtivo | L4: Retroescavadeira
A5: 130 | B5: 130 | C5: S.VP-01438 | D5: Hr Improdutiva Retroescavadeira C/Operador | E5: H | F5: 108.23 | G5: S.VP-01396 | H5: HR IMPRODUTIVA RETROESCAVADEIRA C/OPERADOR | I5: H | J5: 65.42 | K5: Improdutivo | L5: Retroescavadeira
A6: 140 | B6: 140 | C6: S.VP-01439 | D6: Mobilização Pa Carregadeira C/ Operador | E6: VB | F6: 2319.45 | G6: S.VP-01397 | H6: MOBILIZAÇÃO PA CARREGADEIRA C/ OPERADOR | I6: VB | J6: 1045.98 | K6: Mobilização | L6: Pá Carregadeira
A7: 150 | B7: 150 | C7: S.VP-01440 | D7: Desmobilização De Pa Carregadeira C/Operador | E7: VB | F7: 2319.45 | G7: S.VP-01398 | H7: DESMOBILIZAÇÃO DE PA CARREGADEIRA C/OPERADOR | I7: VB | J7: 1045.98 | K7: Desmobilização | L7: Pá Carregadeira
A8: 160 | B8: 160 | C8: S.VP-01441 | D8: Hora Produtiva Pa Carregadeira C/Operador | E8: H | F8: 218.44 | G8: S.VP-01399 | H8: HORA PRODUTIVA PA CARREGADEIRA C/OPERADOR | I8: H | J8: 65.42 | K8: Produtivo | L8: Pá Carregadeira
A9: 170 | B9: 170 | C9: S.VP-01442 | D9: Hora Improdutiva Pa Carregadeira C/Operador | E9: H | F9: 144.96 | G9: S.VP-01400 | H9: HORA IMPRODUTIVA PA CARREGADEIRA C/OPERADOR | I9: H | J9: 65.42 | K9: Improdutivo | L9: Pá Carregadeira
A10: 180 | B10: 180 | C10: S.VP-01443 | D10: Mobilização Caminhão Basculante - C/Motorista | E10: VB | F10: 1137.96 | G10: S.VP-01401 | H10: MOBILIZAÇÃO CAMINHÃO BASCULANTE - C/MOTORISTA | I10: VB | J10: 281.11 | K10: Mobilização | L10: Caminhão Basculante
A11: 190 | B11: 190 | C11: S.VP-01444 | D11: Desmobilização Caminhão Basculante - C/Motorista | E11: VB | F11: 1137.96 | G11: S.VP-01402 | H11: DESMOBILIZAÇÃO CAMINHÃO BASCULANTE - C/MOTORISTA | I11: VB | J11: 281.11 | K11: Desmobilização | L11: Caminhão Basculante
A12: 200 | B12: 200 | C12: S.VP-01445 | D12: Km Rodado Caminhão Basculante - C/Motorista | E12: KM | F12: 7.35 | G12: S.VP-01403 | H12: KM RODADO CAMINHÃO BASCULANTE - C/MOTORISTA | I12: KM | J12: 1.81 | K12: KM | L12: Caminhão Basculante
A13: 210 | B13: 210 | C13: S.VP-01446 | D13: Hora Improdutiva Basculante - C/Motorista | E13: H | F13: 132.89 | G13: S.VP-01404 | H13: HORA IMPRODUTIVA BASCULANTE - C/MOTORISTA | I13: H | J13: 65.42 | K13: Improdutivo | L13: Caminhão Basculante
... A21: 290 | B21: 290 | C21: S.VP-01454 | D21: Hora Improdutiva Motoniveladora C/Operador | E21: H | F21: 193.29 | G21: S.VP-01412 | H21: HORA IMPRODUTIVA MOTONIVELADORA C/OPERADOR | I21: H | J21: 87.27 | K21: Improdutivo | L21: Motoniveladora
A22: 3.25 | B22: 3.25 | C22: S.VP-01455 | D22: Mobilização De Trator Esteira – C/Operador | E22: VB | F22: 2525.62 | G22: S.VP-01413 | H22: MOBILIZAÇÃO DE TRATOR ESTEIRA – C/OPERADOR | I22: VB | J22: 925.23 | K22: Mobilização | L22: Trator de Esteira
A23: 3.26 | B23: 3.26 | C23: S.VP-01456 | D23: Desmobilização De Trator Esteira – C/Operador | E23: VB | F23: 2525.62 | G23: S.VP-01414 | H23: DESMOBILIZAÇÃO DE TRATOR ESTEIRA – C/OPERADOR | I23: VB | J23: 925.23 | K23: Desmobilização | L23: Trator de Esteira
A24: 3.27 | B24: 3.27 | C24: S.VP-01457 | D24: Hora Produtiva Trator Esteira – C/ Operador | E24: H | F24: 326.34 | G24: S.VP-01415 | H24: HORA PRODUTIVA TRATOR ESTEIRA – C/ OPERADOR | I24: H | J24: 65.42 | K24: Produtivo | L24: Trator de Esteira
A25: 3.28 | B25: 3.28 | C25: S.VP-01458 | D25: Hora Improdutiva Trator Esteira – C/ Operador | E25: H | F25: 180.41 | G25: S.VP-01416 | H25: HORA IMPRODUTIVA TRATOR ESTEIRA – C/ OPERADOR | I25: H | J25: 65.42 | K25: Improdutivo | L25: Trator de Esteira
A26: 380 | B26: 380 | C26: S.VP-01459 | D26: Mobilização Carreta Prancha - C/ Motorista | E26: VB | F26: 2236.74 | G26: S.VP-01417 | H26: MOBILIZAÇÃO CARRETA PRANCHA - C/ MOTORISTA | I26: VB | J26: 785.33 | K26: Mobilização | L26: Carreta Prancha
A27: 390 | B27: 390 | C27: S.VP-01460 | D27: Desmobilização Carreta Prancha - C/ Motorista | E27: VB | F27: 2236.74 | G27: S.VP-01418 | H27: DESMOBILIZAÇÃO CARRETA PRANCHA - C/ MOTORISTA | I27: VB | J27: 785.33 | K27: Desmobilização | L27: Carreta Prancha
A28: 400 | B28: 400 | C28: S.VP-01461 | D28: Km Rodado Carreta Prancha - C/ Motorista | E28: KM | F28: 7.1 | G28: S.VP-01419 | H28: KM RODADO CARRETA PRANCHA - C/ MOTORISTA | I28: KM | J28: 2.5 | K28: KM | L28: Carreta Prancha
A29: 410 | B29: 410 | C29: S.VP-01462 | D29: Hora Improdutiva Carreta Prancha - C/ Motorista | E29: H | F29: 112.76 | G29: S.VP-01420 | H29: HORA IMPRODUTIVA CARRETA PRANCHA - C/ MOTORISTA | I29: H | J29: 87.27 | K29: Improdutivo | L29: Carreta Prancha
A30: 460 | B30: 460 | C30: S.VP-01463 | D30: Mobilização Miniescavadeira C/ Operador | E30: VB | F30: 1455.25 | G30: S.VP-01421 | H30: MOBILIZAÇÃO MINIESCAVADEIRA C/ OPERADOR | I30: VB | J30: 908.705 | K30: Mobilização | L30: Miniescavadeira
A31: 470 | B31: 470 | C31: S.VP-01464 | D31: Desmobilização Miniescavadeira C/ Operador | E31: VB | F31: 1455.25 | G31: S.VP-01422 | H31: DESMOBILIZAÇÃO MINIESCAVADEIRA C/ OPERADOR | I31: VB | J31: 908.7 | K31: Desmobilização | L31: Miniescavadeira
A32: 480 | B32: 480 | C32: S.VP-01465 | D32: Hora Produtiva Miniescavadeira Hidraulica C/ Operador | E32: H | F32: 138.38 | G32: S.VP-01423 | H32: HORA PRODUTIVA MINIESCAVADEIRA HIDRAULICA C/ OPERADOR | I32: H | J32: 65.42 | K32: Produtivo | L32: Miniescavadeira
A33: 490 | B33: 490 | C33: S.VP-01466 | D33: Hora Improdutiva Miniescavadeira Hidraulica C/ Operador | E33: H | F33: 104.71 | G33: S.VP-01424 | H33: HORA IMPRODUTIVA MINIESCAVADEIRA HIDRAULICA C/ OPERADOR | I33: H | J33: 65.42 | K33: Improdutivo | L33: Miniescavadeira
A34: 500 | B34: 500 | C34: S.VP-01467 | D34: Mobilização Escavadeira Hidraulica | E34: VB | F34: 4625.9 | G34: S.VP-01425 | H34: MOBILIZAÇÃO ESCAVADEIRA HIDRAULICA | I34: VB | J34: 1632.59 | K34: Mobilização | L34: Escavadeira Hidráulica
A35: 510 | B35: 510 | C35: S.VP-01468 | D35: Desmobilização Escavadeira Hidraulica | E35: VB | F35: 4625.9 | G35: S.VP-01426 | H35: DESMOBILIZAÇÃO ESCAVADEIRA HIDRAULICA | I35: VB | J35: 1632.595 | K35: Desmobilização | L35: Escavadeira Hidráulica
A36: 520 | B36: 520 | C36: S.VP-01469 | D36: Hora Produtiva Escavadeira Hidraulica | E36: H | F36: 283.19 | G36: S.VP-01427 | H36: HORA PRODUTIVA ESCAVADEIRA HIDRAULICA | I36: H | J36: 65.42 | K36: Produtivo | L36: Escavadeira Hidráulica
A37: 530 | B37: 530 | C37: S.VP-01470 | D37: Hora Improdutiva Escavadeira Hidraulica | E37: H | F37: 185.23 | G37: S.VP-01428 | H37: HORA IMPRODUTIVA ESCAVADEIRA HIDRAULICA | I37: H | J37: 65.42 | K37: Improdutivo | L37: Escavadeira Hidráulica
A38: 3.41 | B38: 3.41 | C38: S.VP-01471 | D38: Mobilização Rolo Compactador C/ Operador | E38: VB | F38: 1872.58 | G38: S.VP-01429 | H38: MOBILIZAÇÃO ROLO COMPACTADOR C/ OPERADOR | I38: VB | J38: 1013.3 | K38: Mobilização | L38: Rolo Compactador
A39: 3.42 | B39: 3.42 | C39: S.VP-01472 | D39: Desmobilização Rolo Compactador C/ Operador | E39: VB | F39: 1590.13 | G39: S.VP-01430 | H39: DESMOBILIZAÇÃO ROLO COMPACTADOR C/ OPERADOR | I39: VB | J39: 697.8 | K39: Desmobilização | L39: Rolo Compactador
A40: 3.43 | B40: 3.43 | C40: S.VP-01473 | D40: Hora Produtiva Rolo Compactador C/Operador | E40: H | F40: 163.66 | G40: S.VP-01431 | H40: HORA PRODUTIVA ROLO COMPACTADOR C/OPERADOR | I40: H | J40: 65.42 | K40: Produtivo | L40: Rolo Compactador
A41: 3.44 | B41: 3.44 | C41: S.VP-01474 | D41: Hora Improdutiva Rolo Compactador C/Operador | E41: H | F41: 120.81 | G41: S.VP-01432 | H41: HORA IMPRODUTIVA ROLO COMPACTADOR C/OPERADOR | I41: H | J41: 65.42 | K41: Improdutivo | L41: Rolo Compactador
A42: 580 | B42: 580 | C42: S.VP-01475 | D42: Transporte Rodoviario Carro 5 Passageiros | E42: MES | F42: 16354.1 | L42: Veículo Leve
A43: 590 | B43: 590 | C43: S.VP-01476 | D43: Transporte Rodoviario Carro 7 Passageiros | E43: MES | F43: 17419.43 | L43: Veículo Leve

Sheet RESUMO DR
K1: EGPs | M1: Caminhões
I2: Total de frota | J2: =SUM(J3:J5) -> 18 | K2: RE-018 | M2: CB-009 | N2: CM-002/SR-005 | P2: VL-041
I3: EGPs | J3: =COUNTA(K2:L9) -> 8 | K3: RE-017 | L3: MN-002 | M3: CB-010 | P3: VL-051
B4: MEDIÇÃO VLI 2015 DR ENGENHARIA 16/12/24 a 20/01/2025 | I4: Caminhões | J4: =COUNTA(M2:N9) -> 7 | L4: MNL-001 | M4: CB-013 | P4: Localiza
I5: VL | J5: =COUNTA(P2:P9) -> 3 | K5: EH-008 | M5: CB-014
B6: CONTRATO 4994 | K6: PC-002 | M6: CB-022
B7: RESUMO POR MUNICÍPIO | K7: PC-004 | M7: CBL-001
B8: MUNICÍPIOS | C8: VALOR R$ | D8: SUPERVISÃO | E8: Trecho | K8: PCL-001
B9: Ribamar Fiquene | C9: =SUMIF('REAL DR'!J37:J1755,"RIBAMAR FIQUENE",'REAL DR'!Q37:Q1755) -> #VALUE! | D9: =IF(E9<>"",VLOOKUP(E9,'RESUMO DR'!$F$10:$G$20,2,FALSE),"") -> IMPERATRIZ | E9: T-01 | F9: SUPERVISÃO
B10: Campestre | C10: =SUMIF('REAL DR'!J37:J1755,"campestre",'REAL DR'!Q37:Q1755) -> #VALUE! | D10: =IF(E10<>"",VLOOKUP(E10,'RESUMO DR'!$F$10:$G$20,2,FALSE),"") -> IMPERATRIZ | E10: T-01 | F10: T-01 | G10: IMPERATRIZ | H10: =SUMIF(E9:E34,"T-01",C9:C34) -> #VALUE! | I10: Araguaina | J10: S.Luiz
B11: Porto Franco | C11: =SUMIF('REAL DR'!J37:J1355,"PORTO FRANCO",'REAL DR'!Q37:Q1355) -> #VALUE! | D11: =IF(E11<>"",VLOOKUP(E11,'RESUMO DR'!$F$10:$G$20,2,FALSE),"") -> IMPERATRIZ | E11: T-01 | F11: T-02 | G11: ARAGUAINA | H11: =SUMIF(E9:E34,"T-02",C9:C34) -> #VALUE! | I11: =H11-C13 -> #VALUE! | J11: =H11-I11 -> #VALUE! | K11: FROTA | L11: ITEM | M11: CÓDIGO SAP | N11: Descrição | O11: Und. | P11: Preço (R$) | Q11: Qde EGP | R11: Qde hrs | S11: Qde dias | T11: Qde dias perda | U11: HORAS/MÊS | V11: FATURAMENTO MÁXIMO | W11: TOTAL (R$) DIA | X11: TOTAL (R$) MÊS | Y11: TOTAL (R$) MÊS + Perdas
B12: Imperatriz | C12: =SUMIF('REAL DR'!J37:J1755,"IMPERATRIZ",'REAL DR'!Q37:Q1755) -> #VALUE! | D12: =IF(E12<>"",VLOOKUP(E12,'RESUMO DR'!$F$10:$G$20,2,FALSE),"") -> IMPERATRIZ | E12: T-01 | F12: T-03 | G12: PALMAS | H12: =SUMIF(E9:E34,"T-03",C9:C34) -> #VALUE! | L12: 120 | M12: =IF(L12<>"",VLOOKUP(L12,'Catálogo SAP'!$A$1:$F$245,2,FALSE),"-") -> 120 | N12: =IF(L12<>"",VLOOKUP(L12,'Catálogo SAP'!A:F,3,FALSE),"") -> S.VP-01437 | O12: =IF(M12<>"",VLOOKUP(M12,'Catálogo SAP'!C:F,3,FALSE),"") -> #N/A | P12: =IF(N12<>"",VLOOKUP(N12,'Catálogo SAP'!D:F,3,FALSE),"") -> #N/A | Q12: 2 | R12: 9 | S12: 22 | T12: 19 | U12: 176 | V12: =P12*Q12*U12 -> #N/A | W12: =R12*Q12*P12 -> #N/A | X12: =S12*W12 -> #N/A | Y12: =T12*W12 -> #N/A | Z12: =Y12/X12 -> #N/A
B13: Sao Luis | C13: =SUMIF('REAL DR'!J37:J1755,"SAO LUIS",'REAL DR'!Q37:Q1755) -> #VALUE! | D13: =IF(E13<>"",VLOOKUP(E13,'RESUMO DR'!$F$10:$G$20,2,FALSE),"") -> ARAGUAINA | E13: T-02 | F13: T-04 | G13: ENG. VLI | H13: =SUMIF(E10:E35,"T-04",C10:C35) -> 0 | L13: 130 | M13: =IF(L13<>"",VLOOKUP(L13,'Catálogo SAP'!$A$1:$F$245,2,FALSE),"-") -> 130 | N13: =IF(L13<>"",VLOOKUP(L13,'Catálogo SAP'!A:F,3,FALSE),"") -> S.VP-01438 | O13: =IF(M13<>"",VLOOKUP(M13,'Catálogo SAP'!C:F,3,FALSE),"") -> #N/A | P13: =IF(N13<>"",VLOOKUP(N13,'Catálogo SAP'!D:F,3,FALSE),"") -> #N/A | W13: =(Q13*R13)*P13 -> #N/A | X13: =S13*W13 -> #N/A | Y13: =T13*W13 -> #N/A | Z13: =Y13/X13 -> #N/A
B14: João Lisboa | C14: =SUMIF('REAL DR'!J37:J1755,"JOÃO LISBOA",'REAL DR'!Q37:Q1755) -> #VALUE! | D14: =IF(E14<>"",VLOOKUP(E14,'RESUMO DR'!$F$10:$G$20,2,FALSE),"") -> IMPERATRIZ | E14: T-01 | F14: VL | G14: VL! - 2015 | H14: =C33 -> 0 | L14: 160 | M14: =IF(L14<>"",VLOOKUP(L14,'Catálogo SAP'!$A$1:$F$245,2,FALSE),"-") -> 160 | N14: =IF(L14<>"",VLOOKUP(L14,'Catálogo SAP'!A:F,3,FALSE),"") -> S.VP-01441 | O14: =IF(M14<>"",VLOOKUP(M14,'Catálogo SAP'!C:F,3,FALSE),"") -> #N/A | P14: =IF(N14<>"",VLOOKUP(N14,'Catálogo SAP'!D:F,3,FALSE),"") -> #N/A | Q14: 2 | R14: 9 | S14: 22 | T14: 18 | U14: 176 | V14: =P14*Q14*U14 -> #N/A | W14: =(Q14*R14)*P14 -> #N/A | X14: =S14*W14 -> #N/A | Y14: =T14*W14 -> #N/A | Z14: =Y14/X14 -> #N/A
B15: Açailândia | C15: =SUMIF('REAL DR'!J37:J1756,"AÇAILÂNDIA",'REAL DR'!Q37:Q1756) -> 0 | D15: =IF(E15<>"",VLOOKUP(E15,'RESUMO DR'!$F$10:$G$20,2,FALSE),"") -> IMPERATRIZ | E15: T-01 | F15: Total | H15: =SUM(H10:H14) -> #VALUE! | L15: 170 | M15: =IF(L15<>"",VLOOKUP(L15,'Catálogo SAP'!$A$1:$F$245,2,FALSE),"-") -> 170 | N15: =IF(L15<>"",VLOOKUP(L15,'Catálogo SAP'!A:F,3,FALSE),"") -> S.VP-01442 | O15: =IF(M15<>"",VLOOKUP(M15,'Catálogo SAP'!C:F,3,FALSE),"") -> #N/A | P15: =IF(N15<>"",VLOOKUP(N15,'Catálogo SAP'!D:F,3,FALSE),"") -> #N/A | W15: =(Q15*R15)*P15 -> #N/A | X15: =S15*W15 -> #N/A | Y15: =T15*W15 -> #N/A | Z15: =Y15/X15 -> #N/A
B16: S.F. Brejão | C16: =SUMIF('REAL DR'!J37:J1857,"S.F. BREJÃO",'REAL DR'!Q37:Q1857) -> #VALUE! | D16: =IF(E16<>"",VLOOKUP(E16,'RESUMO DR'!$F$10:$G$20,2,FALSE),"") -> IMPERATRIZ | E16: T-01 | L16: 200 | M16: =IF(L16<>"",VLOOKUP(L16,'Catálogo SAP'!$A$1:$F$245,2,FALSE),"-") -> 200 | N16: =IF(L16<>"",VLOOKUP(L16,'Catálogo SAP'!A:F,3,FALSE),"") -> S.VP-01445 | O16: =IF(M16<>"",VLOOKUP(M16,'Catálogo SAP'!C:F,3,FALSE),"") -> #N/A | P16: =IF(N16<>"",VLOOKUP(N16,'Catálogo SAP'!D:F,3,FALSE),"") -> #N/A | Q16: 4 | R16: 9 | S16: 22 | T16: 19 | U16: 176 | V16: =U16*P16*Q16 -> #N/A | W16: =(Q16*R16)*P16 -> #N/A | X16: =S16*W16 -> #N/A | Y16: =T16*W16 -> #N/A | Z16: =Y16/X16 -> #N/A
B17: Edson Lobão | C17: =SUMIF('REAL DR'!J37:J1755,"EDSON LOBÃO",'REAL DR'!Q37:Q1755) -> #VALUE! | D17: =IF(E17<>"",VLOOKUP(E17,'RESUMO DR'!$F$10:$G$20,2,FALSE),"") -> IMPERATRIZ | E17: T-01 | L17: 210 | M17: =IF(L17<>"",VLOOKUP(L17,'Catálogo SAP'!$A$1:$F$245,2,FALSE),"-") -> 210 | N17: =IF(L17<>"",VLOOKUP(L17,'Catálogo SAP'!A:F,3,FALSE),"") -> S.VP-01446 | O17: =IF(M17<>"",VLOOKUP(M17,'Catálogo SAP'!C:F,3,FALSE),"") -> #N/A | P17: =IF(N17<>"",VLOOKUP(N17,'Catálogo SAP'!D:F,3,FALSE),"") -> #N/A | W17: =(Q17*R17)*P17 -> #N/A | X17: =S17*W17 -> #N/A | Y17: =T17*W17 -> #N/A | Z17: =Y17/X17 -> #N/A
B18: Palmeirante | C18: =SUMIF('REAL DR'!J37:J2077,"Palmeirante",'REAL DR'!Q37:Q2077) -> #VALUE! | D18: =IF(E18<>"",VLOOKUP(E18,'RESUMO DR'!$F$10:$G$22,2,FALSE),"") -> ARAGUAINA | E18: T-02 | L18: 280 | M18: =IF(L18<>"",VLOOKUP(L18,'Catálogo SAP'!$A$1:$F$245,2,FALSE),"-") -> 280 | N18: =IF(L18<>"",VLOOKUP(L18,'Catálogo SAP'!A:F,3,FALSE),"") -> S.VP-01453 | O18: =IF(M18<>"",VLOOKUP(M18,'Catálogo SAP'!C:F,3,FALSE),"") -> #N/A | P18: =IF(N18<>"",VLOOKUP(N18,'Catálogo SAP'!D:F,3,FALSE),"") -> #N/A | Q18: 1 | R18: 9 | S18: 22 | T18: 19 | U18: 176 | V18: =P18*Q18*U18 -> #N/A | W18: =(Q18*R18)*P18 -> #N/A | X18: =S18*W18 -> #N/A | Y18: =T18*W18 -> #N/A | Z18: =Y18/X18 -> #N/A
B19: Tupiratins | C19: =SUMIF('REAL DR'!J37:J1757,"Tupiratins",'REAL DR'!Q37:Q1757) -> #VALUE! | D19: =IF(E19<>"",VLOOKUP(E19,'RESUMO DR'!$F$10:$G$22,2,FALSE),"") -> PALMAS | E19: T-03 | L19: 290 | M19: =IF(L19<>"",VLOOKUP(L19,'Catálogo SAP'!$A$1:$F$245,2,FALSE),"-") -> 290 | N19: =IF(L19<>"",VLOOKUP(L19,'Catálogo SAP'!A:F,3,FALSE),"") -> S.VP-01454 | O19: =IF(M19<>"",VLOOKUP(M19,'Catálogo SAP'!C:F,3,FALSE),"") -> #N/A | P19: =IF(N19<>"",VLOOKUP(N19,'Catálogo SAP'!D:F,3,FALSE),"") -> #N/A | W19: =(Q19*R19)*P19 -> #N/A | X19: =S19*W19 -> #N/A | Y19: =T19*W19 -> #N/A | Z19: =Y19/X19 -> #N/A
B20: Guaraí | C20: =SUMIF('REAL DR'!J37:J1729,"Guaraí",'REAL DR'!Q37:Q1729) -> #VALUE! | D20: =IF(E20<>"",VLOOKUP(E20,'RESUMO DR'!$F$10:$G$22,2,FALSE),"") -> PALMAS | E20: T-03 | L20: 240 | M20: =IF(L20<>"",VLOOKUP(L20,'Catálogo SAP'!$A$1:$F$245,2,FALSE),"-") -> 240 | N20: =IF(L20<>"",VLOOKUP(L20,'Catálogo SAP'!A:F,3,FALSE),"") -> S.VP-01449 | O20: =IF(M20<>"",VLOOKUP(M20,'Catálogo SAP'!C:F,3,FALSE),"") -> #N/A | P20: =IF(N20<>"",VLOOKUP(N20,'Catálogo SAP'!D:F,3,FALSE),"") -> #N/A | R20: 9 | W20: =(Q20*R20)*P20 -> #N/A | X20: =S20*W20 -> #N/A | Y20: =T20*W20 -> #N/A | Z20: =Y20/X20 -> #N/A
B21: Tupirama | C21: =SUMIF('REAL DR'!J37:J1730,"Tupirama",'REAL DR'!Q37:Q1730) -> #VALUE! | D21: =IF(E21<>"",VLOOKUP(E21,'RESUMO DR'!$F$10:$G$22,2,FALSE),"") -> PALMAS | E21: T-03 | L21: 250 | M21: =IF(L21<>"",VLOOKUP(L21,'Catálogo SAP'!$A$1:$F$245,2,FALSE),"-") -> 250 | N21: =IF(L21<>"",VLOOKUP(L21,'Catálogo SAP'!A:F,3,FALSE),"") -> S.VP-01450 | O21: =IF(M21<>"",VLOOKUP(M21,'Catálogo SAP'!C:F,3,FALSE),"") -> #N/A | P21: =IF(N21<>"",VLOOKUP(N21,'Catálogo SAP'!D:F,3,FALSE),"") -> #N/A | Q21: 2 | R21: 9 | S21: 22 | T21: 22 | U21: =176+36 -> 212 | V21: =U21*Q21*P21 -> #N/A | W21: =(Q21*R21)*P21 -> #N/A | X21: =S21*W21 -> #N/A | Y21: =T21*W21 -> #N/A | Z21: =Y21/X21 -> #N/A
B22: Rio dos Bois | C22: =SUMIF('REAL DR'!J37:J1731,"Rio dos Bois",'REAL DR'!Q37:Q1731) -> 0 | D22: =IF(E22<>"",VLOOKUP(E22,'RESUMO DR'!$F$10:$G$22,2,FALSE),"") -> PALMAS | E22: T-03 | L22: 400 | M22: =IF(L22<>"",VLOOKUP(L22,'Catálogo SAP'!$A$1:$F$245,2,FALSE),"-") -> 400 | N22: =IF(L22<>"",VLOOKUP(L22,'Catálogo SAP'!A:F,3,FALSE),"") -> S.VP-01461 | O22: =IF(M22<>"",VLOOKUP(M22,'Catálogo SAP'!C:F,3,FALSE),"") -> #N/A | P22: =IF(N22<>"",VLOOKUP(N22,'Catálogo SAP'!D:F,3,FALSE),"") -> #N/A | Q22: 1 | R22: 9 | S22: 22 | T22: 10 | U22: 120 | V22: =U22*Q22*P22 -> #N/A | W22: =(Q22*R22)*P22 -> #N/A | X22: =S22*W22 -> #N/A | Y22: =T22*W22 -> #N/A | Z22: =Y22/X22 -> #N/A
B23: Miracema | C23: =SUMIF('REAL DR'!J37:J1755,"Miracema",'REAL DR'!Q37:Q1755) -> 0 | D23: =IF(E23<>"",VLOOKUP(E23,'RESUMO DR'!$F$10:$G$22,2,FALSE),"") -> PALMAS | E23: T-03 | L23: 410 | M23: =IF(L23<>"",VLOOKUP(L23,'Catálogo SAP'!$A$1:$F$245,2,FALSE),"-") -> 410 | N23: =IF(L23<>"",VLOOKUP(L23,'Catálogo SAP'!A:F,3,FALSE),"") -> S.VP-01462 | O23: =IF(M23<>"",VLOOKUP(M23,'Catálogo SAP'!C:F,3,FALSE),"") -> #N/A | P23: =IF(N23<>"",VLOOKUP(N23,'Catálogo SAP'!D:F,3,FALSE),"") -> #N/A | Q23: 1 | R23: 9 | U23: 176 | V23: =U23*P23*Q23 -> #N/A | W23: =(Q23*R23)*P23 -> #N/A | X23: =S23*W23 -> #N/A | Y23: =T23*W23 -> #N/A | Z23: =Y23/X23 -> #N/A
B24: Porto Nacional | C24: =SUMIF('REAL DR'!J37:J1755,"Porto Nacional",'REAL DR'!Q37:Q1755) -> 0 | D24: =IF(E24<>"",VLOOKUP(E24,'RESUMO DR'!$F$10:$G$22,2,FALSE),"") -> PALMAS | E24: T-03 | L24: 520 | M24: =IF(L24<>"",VLOOKUP(L24,'Catálogo SAP'!$A$1:$F$245,2,FALSE),"-") -> 520 | N24: =IF(L24<>"",VLOOKUP(L24,'Catálogo SAP'!A:F,3,FALSE),"") -> S.VP-01469 | O24: =IF(M24<>"",VLOOKUP(M24,'Catálogo SAP'!C:F,3,FALSE),"") -> #N/A | P24: =IF(N24<>"",VLOOKUP(N24,'Catálogo SAP'!D:F,3,FALSE),"") -> #N/A | Q24: 1 | R24: 9 | S24: 22 | T24: 19 | U24: =120 -> 120 | V24: =U24*P24*Q24 -> #N/A | W24: =(Q24*R24)*P24 -> #N/A | X24: =S24*W24 -> #N/A | Y24: =T24*W24 -> #N/A | Z24: =Y24/X24 -> #N/A
B25: ESTREITO | C25: =SUMIF('REAL DR'!J37:J1757,"ESTREITO",'REAL DR'!Q37:Q1757) -> 0 | D25: =IF(E25<>"",VLOOKUP(E25,'RESUMO DR'!$F$10:$G$22,2,FALSE),"") -> ARAGUAINA | E25: T-02 | L25: 530 | M25: =IF(L25<>"",VLOOKUP(L25,'Catálogo SAP'!$A$1:$F$245,2,FALSE),"-") -> 530 | N25: =IF(L25<>"",VLOOKUP(L25,'Catálogo SAP'!A:F,3,FALSE),"") -> S.VP-01470 | O25: =IF(M25<>"",VLOOKUP(M25,'Catálogo SAP'!C:F,3,FALSE),"") -> #N/A | P25: =IF(N25<>"",VLOOKUP(N25,'Catálogo SAP'!D:F,3,FALSE),"") -> #N/A | W25: =(Q25*R25)*P25 -> #N/A | X25: =S25*W25 -> #N/A | Y25: =T25*W25 -> #N/A | Z25: =Y25/X25 -> #N/A
B26: AGUIARNÓPOLIS | C26: =SUMIF('REAL DR'!J37:J1756,"AGUIARNÓPOLIS",'REAL DR'!Q37:Q1756) -> #VALUE! | D26: =IF(E26<>"",VLOOKUP(E26,'RESUMO DR'!$F$10:$G$22,2,FALSE),"") -> ARAGUAINA | E26: T-02 | H26: Fechamento Imperatriz | J26: 553312.96 | L26: 220 | M26: =IF(L26<>"",VLOOKUP(L26,'Catálogo SAP'!$A$1:$F$245,2,FALSE),"-") -> 220 | N26: =IF(L26<>"",VLOOKUP(L26,'Catálogo SAP'!A:F,3,FALSE),"") -> S.VP-01447 | O26: =IF(M26<>"",VLOOKUP(M26,'Catálogo SAP'!C:F,3,FALSE),"") -> #N/A | P26: =IF(N26<>"",VLOOKUP(N26,'Catálogo SAP'!D:F,3,FALSE),"") -> #N/A | Q26: 0 | R26: 1 | V26: =U26*P26 -> #N/A | W26: =(Q26*R26)*P26 -> #N/A | X26: =S26*W26 -> #N/A | Y26: =T26*W26 -> #N/A | Z26: =Y26/X26 -> #N/A
B27: PALMEIRAS DO TOCANTINS | C27: =SUMIF('REAL DR'!J37:J1757,"PALMEIRAS DO TOCANTINS",'REAL DR'!Q37:Q1757) -> 0 | D27: =IF(E27<>"",VLOOKUP(E27,'RESUMO DR'!$F$10:$G$22,2,FALSE),"") -> ARAGUAINA | E27: T-02 | L27: 580 | M27: =IF(L27<>"",VLOOKUP(L27,'Catálogo SAP'!$A$1:$F$245,2,FALSE),"-") -> 580 | N27: =IF(L27<>"",VLOOKUP(L27,'Catálogo SAP'!A:F,3,FALSE),"") -> S.VP-01475 | O27: =IF(M27<>"",VLOOKUP(M27,'Catálogo SAP'!C:F,3,FALSE),"") -> #N/A | P27: =IF(N27<>"",VLOOKUP(N27,'Catálogo SAP'!D:F,3,FALSE),"") -> #N/A | Q27: 1 | R27: 1 | T27: 1 | U27: 1 | V27: =Q27*P27 -> #N/A | W27: =(Q27*R27)*P27 -> #N/A | X27: =S27*W27 -> #N/A | Y27: =T27*W27 -> #N/A | Z27: =Y27/X27 -> #N/A
M28: S.VPP-00785 | N28: MOBILIZAÇÃO MINIESCAVADEIRA | O28: VB | P28: 2440.43 | Q28: 1 | U28: 1 | V28: =U28*P28 -> 2440.43
B29: DARCINÓPOLIS | C29: =SUMIF('REAL DR'!J37:J1758,"DARCINÓPOLIS",'REAL DR'!Q37:Q1758) -> 0 | D29: =IF(E29<>"",VLOOKUP(E29,'RESUMO DR'!$F$10:$G$22,2,FALSE),"") -> ARAGUAINA | E29: T-02 | M29: S.VPP-00787 | N29: HORA PRODUTIVA MINIESCAVADEIRA | O29: HP | P29: 241.06 | Q29: 1 | S29: 10 | U29: 90 | V29: =U29*P29 -> 21695.4 | X29: =SUM(X12:X27) -> #N/A | Y29: =SUM(Y12:Y27) -> #N/A | Z29: Faturado | AA29: DESVIO | AB29: Perda valor
B30: BABAÇULÂNDIA | C30: =SUMIF('REAL DR'!J37:J1355,"BABAÇULÂNDIA",'REAL DR'!Q37:Q1355) -> #VALUE! | D30: =IF(E30<>"",VLOOKUP(E30,'RESUMO DR'!$F$10:$G$22,2,FALSE),"") -> ARAGUAINA | E30: T-02 | M30: S.VPP-00788 | N30: HORA IMPRODUTIVA MINIESCAVADEIRA | O30: HI | P30: 190.52 | Z30: =Y29/X29 -> #N/A | AA30: =1-Z30 -> #N/A | AB30: =X29-W29 -> #N/A
B31: ARAGUAÍNA | C31: =SUMIF('REAL DR'!J37:J1865,"ARAGUAÍNA",'REAL DR'!Q37:Q1865) -> #VALUE! | D31: =IF(E31<>"",VLOOKUP(E31,'RESUMO DR'!$F$10:$G$22,2,FALSE),"") -> ARAGUAINA | E31: T-02 | Y31: =Y29+60000 -> #N/A | Z31: 45145
B32: PT Porto Franco | C32: =SUMIF('REAL DR'!J37:J1357,"PT Porto Franco",'REAL DR'!Q37:Q1357) -> 0 | D32: =IF(E32<>"",VLOOKUP(E32,'RESUMO DR'!$F$10:$G$22,2,FALSE),"") -> IMPERATRIZ | E32: T-01 | Y32: =Y31*0.82 -> #N/A | Z32: 45145
B33: ENG. VLI | C33: =SUMIF('REAL DR'!J37:J1358,"ENG.VLI",'REAL DR'!Q37:Q1358) -> 0 | D33: =IF(E33<>"",VLOOKUP(E33,'RESUMO DR'!$F$10:$G$22,2,FALSE),"") -> ENG. VLI | E33: T-04
D34: =IF(E34<>"",VLOOKUP(E34,'RESUMO DR'!$F$10:$G$22,2,FALSE),"") | Y34: =775749.92 -> 775749.92
B35: TOTAL | C35: =SUM(C9:C34) -> #VALUE! | Y35: =Y34*0.82 -> 636114.93
K36: Caso 100% realizado se programado | Y36: =Y35-Y34 -> -139634.99
B37: Gestor: | C37: Tharcísio Pereira | K37: EQ | M37: HP | N37: HI | O37: Dia Tb 9hs | R37: Dia Tb 8hs | T37: Soma Total HP | W37: Horas total
K38: PC | L38: 1 | M38: 251.96 | N38: 191.73 | O38: 16 | P38: 9 | R38: 4 | S38: 8 | T38: =M38*W38 -> 44344.96 | W38: =((O38*P38)+(R38*S38))*L38 -> 176
K39: RE | L39: 2 | M39: 149.45 | N39: 133.62 | O39: 16 | P39: 9 | R39: 4 | S39: 8 | T39: =M39*W39 -> 52606.4 | W39: =((O39*P39)+(R39*S39))*L39 -> 352
K40: CB | L40: 4 | M40: 181.92 | N40: 146.21 | O40: 16 | P40: 9 | R40: 4 | S40: 8 | T40: =M40*W40 -> 128071.68 | W40: =((O40*P40)+(R40*S40))*L40 -> 704
...

Sheet Planilha1
A1: CONTROLE DE VIAGENS DE TRANSPORTE DE MATERIAL
A2: Motorista: | G2: Código de frota | I2: Placa
A4: DATA | B4: COMPRIMENTO | D4: LARGURA | E4: ALTURA 1 | F4: ALTURA 2 | G4: ALTURA 3 | H4: MÉDIA | I4: VOLUME | J4: Nº ROMANEIRO | K4: HORA DA CARGA | L4: HORA DA DESCARGA | M4: ASSINATURA FORNECEDOR

Sheet ITENS SAP
A1: DR CONSTRUTORA E SERVIÇOS LTDA
A2: RDO | B2: DIA | C2: MUNICÍPIO | D2: CÓDIGO DO RDO | E2: NÚMERO
A3: 1728 | B3: ='[1]Medição '!D2 -> 43851 | C3: SÃO LUIS | D3: 120 | E3: S.VPP-00120
A4: 1728 | B4: ='[1]Medição '!D3 -> 43851 | C4: SÃO LUIS | D4: 130 | E4: S.VPP-00118
A5: 1727 | B5: ='[1]Medição '!D4 -> 43851 | C5: IMPERATRIZ | D5: 200 | E5: S.VPP-00758
A6: 1727 | B6: ='[1]Medição '!D5 -> 43851 | C6: IMPERATRIZ | D6: 210 | E6: S.VPP-00759
A7: 1727 | B7: ='[1]Medição '!D6 -> 43851 | C7: IMPERATRIZ | D7: 170 | E7: S.VPP-00755
A8: 1727 | B8: ='[1]Medição '!D7 -> 43851 | C8: IMPERATRIZ | D8: 290 | E8: S.VPP-00767
A9: 1729 | B9: ='[1]Medição '!D8 -> 43852 | C9: SÃO LUIS | D9: 120 | E9: S.VPP-00120
A10: 1729 | B10: ='[1]Medição '!D9 -> 43852 | C10: SÃO LUIS | D10: 130 | E10: S.VPP-00118
A11: 1730 | B11: ='[1]Medição '!D10 -> 43852 | C11: IMPERATRIZ | D11: 200 | E11: S.VPP-00758
A12: 1730 | B12: ='[1]Medição '!D11 -> 43852 | C12: IMPERATRIZ | D12: 210 | E12: S.VPP-00759
A13: 1730 | B13: ='[1]Medição '!D12 -> 43852 | C13: IMPERATRIZ | D13: 170 | E13: S.VPP-00755
A14: 1730 | B14: ='[1]Medição '!D13 -> 43852 | C14: IMPERATRIZ | D14: 290 | E14: S.VPP-00767
... A149: 1784 | B149: ='[1]Medição '!D148 -> 43880 | C149: JOAO LISBOA | D149: 290 | E149: S.VPP-00767
A152: Supervisor DR Construtora | D152: Fiscal VLI

Sheet REAL DR
A1: ='RESUMO DR'!B4 -> MEDIÇÃO VLI 2015 DR ENGENHARIA 16/12/24 a 20/01/2025
L3: Total Medição = | Q3: =SUM(Q6:Q1004) -> #VALUE!
A5: RDO | B5: Data | C5: FROTA | D5: Semana | E5: CÓDIGO SAP | F5: Horimetro Inicial | G5: Horimetro Final | H5: KM INICIAL | I5: KM FINAL | J5: Município | K5: Item | L5: Descrição | M5: Und. | N5: Preço (R$) | O5: Quant. De Hrs | P5: HM | Q5: TOTAL (R$) | R5: SUPERVISÃO | S5: CENTRO | T5: KM IN | U5: KM FN | V5: LITROS | W5: VALOR | X5: MEDIA Veiculos | Y5: Media EGP | Z5: Observações
A6: 1786 | B6: 45642 | C6: REL-04 | D6: =IF(B6="","-",TEXT(B6,"ddd")) -> seg | E6: =IF(K6<>"",VLOOKUP(K6,'Catálogo SAP'!$A$1:$F$245,2,FALSE),"-") -> 120 | F6: 96 | G6: 102 | I6: 452 | J6: =IF(AND(I6>=0.001,I6<=16),"AÇAILÂNDIA","")&IF(AND(I6>=16.001,I6<=44),"S.F. BREJÃO","")&IF(AND(I6>=44.001,I6<=78),"JOÃO LISBOA","")&IF(AND(I6>=78.001,I6<=96.397),"IMPERATRIZ","")&IF(AND(I6>=96.398,I6<=122.82),"EDSON LOBÃO","")&IF(AND(I6>=122.821,I6<=152.303),"RIBAMAR FIQUENE","")&IF(AND(I6>=152.304,I6<=172.403),"CAMPESTRE","")&IF(AND(I6>=172.404,I6<=195),"PORTO FRANCO","")&IF(AND(I6>=300,I6<=300),"SAO LUIS","")&IF(AND(I6>=385.4,I6<=465.4),"Palmeirante","")&IF(AND(I6>=465.401,I6<=520.455),"Tupiratins","")&IF(AND(I6>=520.456,I6<=536.741),"Guaraí","")&IF(AND(I6>=536.742,I6<=580.293),"Tupirama","")&IF(AND(I6>=580.294,I6<=608.637),"Rio dos Bois","")&IF(AND(I6>=608.638,I6<=698.981),"Miracema","")&IF(AND(I6>=698.982,I6<=735.6),"Porto Nacional","")&IF(AND(I6>=195.1,I6<=213.603),"ESTREITO","")&IF(AND(I6>=213.604,I6<=218.976),"AGUIARNÓPOLIS","")&IF(AND(I6>=218.977,I6<=253.5),"PALMEIRAS DO TOCANTINS","")&IF(AND(I6>=253.501,I6<=274.15),"DARCINÓPOLIS","")&IF(AND(I6>=274.151,I6<=299.999),"BABAÇULÂNDIA","")&IF(AND(I6>=356.62,I6<=385.4),"ARAGUAÍNA","")&IF(AND(I6>=300.001,I6<=356.619),"BABAÇULÂNDIA","")&IF(AND(I6>=900,I6<=902),"ENG. VLI","") -> Palmeirante | K6: 120 | L6: =IF(K6<>"",VLOOKUP(K6,'Catálogo SAP'!A:F,3,FALSE),"") -> S.VP-01437 | M6: =IF(K6<>"",VLOOKUP(K6,'Catálogo SAP'!A:F,4,FALSE),"") -> Hr Produtiva Retroescavadeira C/Operador | N6: =IF(K6<>"",VLOOKUP(K6,'Catálogo SAP'!A:F,5,FALSE),"") -> H | O6: 6 | P6: =IF(G6="","-",G6-F6) -> 6 | Q6: =IF(K6="","-",N6*O6) -> #VALUE! | R6: T-03 | S6: PALMAS
A7: 1786 | B7: 45642 | C7: REL-04 | D7: =IF(B7="","-",TEXT(B7,"ddd")) -> seg | E7: =IF(K7<>"",VLOOKUP(K7,'Catálogo SAP'!$A$1:$F$245,2,FALSE),"-") -> 130 | F7: 102 | G7: 102 | I7: 452 | J7: =IF(AND(I7>=0.001,I7<=16),"AÇAILÂNDIA","")&IF(AND(I7>=16.001,I7<=44),"S.F. BREJÃO","")&IF(AND(I7>=44.001,I7<=78),"JOÃO LISBOA","")&IF(AND(I7>=78.001,I7<=96.397),"IMPERATRIZ","")&IF(AND(I7>=96.398,I7<=122.82),"EDSON LOBÃO","")&IF(AND(I7>=122.821,I7<=152.303),"RIBAMAR FIQUENE","")&IF(AND(I7>=152.304,I7<=172.403),"CAMPESTRE","")&IF(AND(I7>=172.404,I7<=195),"PORTO FRANCO","")&IF(AND(I7>=300,I7<=300),"SAO LUIS","")&IF(AND(I7>=385.4,I7<=465.4),"Palmeirante","")&IF(AND(I7>=465.401,I7<=520.455),"Tupiratins","")&IF(AND(I7>=520.456,I7<=536.741),"Guaraí","")&IF(AND(I7>=536.742,I7<=580.293),"Tupirama","")&IF(AND(I7>=580.294,I7<=608.637),"Rio dos Bois","")&IF(AND(I7>=608.638,I7<=698.981),"Miracema","")&IF(AND(I7>=698.982,I7<=735.6),"Porto Nacional","")&IF(AND(I7>=195.1,I7<=213.603),"ESTREITO","")&IF(AND(I7>=213.604,I7<=218.976),"AGUIARNÓPOLIS","")&IF(AND(I7>=218.977,I7<=253.5),"PALMEIRAS DO TOCANTINS","")&IF(AND(I7>=253.501,I7<=274.15),"DARCINÓPOLIS","")&IF(AND(I7>=274.151,I7<=299.999),"BABAÇULÂNDIA","")&IF(AND(I7>=356.62,I7<=385.4),"ARAGUAÍNA","")&IF(AND(I7>=300.001,I7<=356.619),"BABAÇULÂNDIA","")&IF(AND(I7>=900,I7<=902),"ENG. VLI","") -> Palmeirante | K7: 130 | L7: =IF(K7<>"",VLOOKUP(K7,'Catálogo SAP'!A:F,3,FALSE),"") -> S.VP-01438 | M7: =IF(K7<>"",VLOOKUP(K7,'Catálogo SAP'!A:F,4,FALSE),"") -> Hr Improdutiva Retroescavadeira C/Operador | N7: =IF(K7<>"",VLOOKUP(K7,'Catálogo SAP'!A:F,5,FALSE),"") -> H | O7: 3 | P7: =IF(G7="","-",G7-F7) -> 0 | Q7: =IF(K7="","-",N7*O7) -> #VALUE! | R7: T-03 | S7: PALMAS
B8: 45642 | C8: RE-018 | D8: =IF(B8="","-",TEXT(B8,"ddd")) -> seg | E8: =IF(K8<>"",VLOOKUP(K8,'Catálogo SAP'!$A$1:$F$245,2,FALSE),"-") -> - | J8: =IF(AND(I8>=0.001,I8<=16),"AÇAILÂNDIA","")&IF(AND(I8>=16.001,I8<=44),"S.F. BREJÃO","")&IF(AND(I8>=44.001,I8<=78),"JOÃO LISBOA","")&IF(AND(I8>=78.001,I8<=96.397),"IMPERATRIZ","")&IF(AND(I8>=96.398,I8<=122.82),"EDSON LOBÃO","")&IF(AND(I8>=122.821,I8<=152.303),"RIBAMAR FIQUENE","")&IF(AND(I8>=152.304,I8<=172.403),"CAMPESTRE","")&IF(AND(I8>=172.404,I8<=195),"PORTO FRANCO","")&IF(AND(I8>=300,I8<=300),"SAO LUIS","")&IF(AND(I8>=385.4,I8<=465.4),"Palmeirante","")&IF(AND(I8>=465.401,I8<=520.455),"Tupiratins","")&IF(AND(I8>=520.456,I8<=536.741),"Guaraí","")&IF(AND(I8>=536.742,I8<=580.293),"Tupirama","")&IF(AND(I8>=580.294,I8<=608.637),"Rio dos Bois","")&IF(AND(I8>=608.638,I8<=698.981),"Miracema","")&IF(AND(I8>=698.982,I8<=735.6),"Porto Nacional","")&IF(AND(I8>=195.1,I8<=213.603),"ESTREITO","")&IF(AND(I8>=213.604,I8<=218.976),"AGUIARNÓPOLIS","")&IF(AND(I8>=218.977,I8<=253.5),"PALMEIRAS DO TOCANTINS","")&IF(AND(I8>=253.501,I8<=274.15),"DARCINÓPOLIS","")&IF(AND(I8>=274.151,I8<=299.999),"BABAÇULÂNDIA","")&IF(AND(I8>=356.62,I8<=385.4),"ARAGUAÍNA","")&IF(AND(I8>=300.001,I8<=356.619),"BABAÇULÂNDIA","")&IF(AND(I8>=900,I8<=902),"ENG. VLI","") | L8: =IF(K8<>"",VLOOKUP(K8,'Catálogo SAP'!A:F,3,FALSE),"") | M8: =IF(K8<>"",VLOOKUP(K8,'Catálogo SAP'!A:F,4,FALSE),"") | N8: =IF(K8<>"",VLOOKUP(K8,'Catálogo SAP'!A:F,5,FALSE),"") | P8: =IF(G8="","-",G8-F8) -> - | Q8: =IF(K8="","-",N8*O8) -> - | R8: =IF(J8<>"",VLOOKUP(J8,'RESUMO DR'!$B$4:$E$253,4,FALSE),"-") -> - | S8: =IF(J8<>"",VLOOKUP(J8,'RESUMO DR'!$B$4:$E$253,3,FALSE),"-") -> -
A9: 1551 | B9: 45642 | C9: RE-017 | D9: =IF(B9="","-",TEXT(B9,"ddd")) -> seg | E9: =IF(K9<>"",VLOOKUP(K9,'Catálogo SAP'!$A$1:$F$245,2,FALSE),"-") -> 120 | F9: 8655 | G9: 8661 | I9: 300 | J9: =IF(AND(I9>=0.001,I9<=16),"AÇAILÂNDIA","")&IF(AND(I9>=16.001,I9<=44),"S.F. BREJÃO","")&IF(AND(I9>=44.001,I9<=78),"JOÃO LISBOA","")&IF(AND(I9>=78.001,I9<=96.397),"IMPERATRIZ","")&IF(AND(I9>=96.398,I9<=122.82),"EDSON LOBÃO","")&IF(AND(I9>=122.821,I9<=152.303),"RIBAMAR FIQUENE","")&IF(AND(I9>=152.304,I9<=172.403),"CAMPESTRE","")&IF(AND(I9>=172.404,I9<=195),"PORTO FRANCO","")&IF(AND(I9>=300,I9<=300),"SAO LUIS","")&IF(AND(I9>=385.4,I9<=465.4),"Palmeirante","")&IF(AND(I9>=465.401,I9<=520.455),"Tupiratins","")&IF(AND(I9>=520.456,I9<=536.741),"Guaraí","")&IF(AND(I9>=536.742,I9<=580.293),"Tupirama","")&IF(AND(I9>=580.294,I9<=608.637),"Rio dos Bois","")&IF(AND(I9>=608.638,I9<=698.981),"Miracema","")&IF(AND(I9>=698.982,I9<=735.6),"Porto Nacional","")&IF(AND(I9>=195.1,I9<=213.603),"ESTREITO","")&IF(AND(I9>=213.604,I9<=218.976),"AGUIARNÓPOLIS","")&IF(AND(I9>=218.977,I9<=253.5),"PALMEIRAS DO TOCANTINS","")&IF(AND(I9>=253.501,I9<=274.15),"DARCINÓPOLIS","")&IF(AND(I9>=274.151,I9<=299.999),"BABAÇULÂNDIA","")&IF(AND(I9>=356.62,I9<=385.4),"ARAGUAÍNA","")&IF(AND(I9>=300.001,I9<=356.619),"BABAÇULÂNDIA","")&IF(AND(I9>=900,I9<=902),"ENG. VLI","") -> SAO LUIS | K9: 120 | L9: =IF(K9<>"",VLOOKUP(K9,'Catálogo SAP'!A:F,3,FALSE),"") -> S.VP-01437 | M9: =IF(K9<>"",VLOOKUP(K9,'Catálogo SAP'!A:F,4,FALSE),"") -> Hr Produtiva Retroescavadeira C/Operador | N9: =IF(K9<>"",VLOOKUP(K9,'Catálogo SAP'!A:F,5,FALSE),"") -> H | O9: 6 | P9: =IF(G9="","-",G9-F9) -> 6 | Q9: =IF(K9="","-",N9*O9) -> #VALUE! | R9: =IF(J9<>"",VLOOKUP(J9,'RESUMO DR'!$B$4:$E$253,4,FALSE),"-") -> T-02 | S9: =IF(J9<>"",VLOOKUP(J9,'RESUMO DR'!$B$4:$E$253,3,FALSE),"-") -> ARAGUAINA
A10: 1551 | B10: 45642 | C10: RE-017 | D10: =IF(B10="","-",TEXT(B10,"ddd")) -> seg | E10: =IF(K10<>"",VLOOKUP(K10,'Catálogo SAP'!$A$1:$F$245,2,FALSE),"-") -> 130 | F10: 8661 | G10: 8661 | I10: 300 | J10: =IF(AND(I10>=0.001,I10<=16),"AÇAILÂNDIA","")&IF(AND(I10>=16.001,I10<=44),"S.F. BREJÃO","")&IF(AND(I10>=44.001,I10<=78),"JOÃO LISBOA","")&IF(AND(I10>=78.001,I10<=96.397),"IMPERATRIZ","")&IF(AND(I10>=96.398,I10<=122.82),"EDSON LOBÃO","")&IF(AND(I10>=122.821,I10<=152.303),"RIBAMAR FIQUENE","")&IF(AND(I10>=152.304,I10<=172.403),"CAMPESTRE","")&IF(AND(I10>=172.404,I10<=195),"PORTO FRANCO","")&IF(AND(I10>=300,I10<=300),"SAO LUIS","")&IF(AND(I10>=385.4,I10<=465.4),"Palmeirante","")&IF(AND(I10>=465.401,I10<=520.455),"Tupiratins","")&IF(AND(I10>=520.456,I10<=536.741),"Guaraí","")&IF(AND(I10>=536.742,I10<=580.293),"Tupirama","")&IF(AND(I10>=580.294,I10<=608.637),"Rio dos Bois","")&IF(AND(I10>=608.638,I10<=698.981),"Miracema","")&IF(AND(I10>=698.982,I10<=735.6),"Porto Nacional","")&IF(AND(I10>=195.1,I10<=213.603),"ESTREITO","")&IF(AND(I10>=213.604,I10<=218.976),"AGUIARNÓPOLIS","")&IF(AND(I10>=218.977,I10<=253.5),"PALMEIRAS DO TOCANTINS","")&IF(AND(I10>=253.501,I10<=274.15),"DARCINÓPOLIS","")&IF(AND(I10>=274.151,I10<=299.999),"BABAÇULÂNDIA","")&IF(AND(I10>=356.62,I10<=385.4),"ARAGUAÍNA","")&IF(AND(I10>=300.001,I10<=356.619),"BABAÇULÂNDIA","")&IF(AND(I10>=900,I10<=902),"ENG. VLI","") -> SAO LUIS | K10: 130 | L10: =IF(K10<>"",VLOOKUP(K10,'Catálogo SAP'!A:F,3,FALSE),"") -> S.VP-01438 | M10: =IF(K10<>"",VLOOKUP(K10,'Catálogo SAP'!A:F,4,FALSE),"") -> Hr Improdutiva Retroescavadeira C/Operador | N10: =IF(K10<>"",VLOOKUP(K10,'Catálogo SAP'!A:F,5,FALSE),"") -> H | O10: 3 | P10: =IF(G10="","-",G10-F10) -> 0 | Q10: =IF(K10="","-",N10*O10) -> #VALUE! | R10: =IF(J10<>"",VLOOKUP(J10,'RESUMO DR'!$B$4:$E$253,4,FALSE),"-") -> T-02 | S10: =IF(J10<>"",VLOOKUP(J10,'RESUMO DR'!$B$4:$E$253,3,FALSE),"-") -> ARAGUAINA
A11: 1785 | B11: 45642 | C11: RE-016 | D11: =IF(B11="","-",TEXT(B11,"ddd")) -> seg | E11: =IF(K11<>"",VLOOKUP(K11,'Catálogo SAP'!$A$1:$F$245,2,FALSE),"-") -> 120 | F11: 5783 | G11: 5792 | I11: 577 | J11: =IF(AND(I11>=0.001,I11<=16),"AÇAILÂNDIA","")&IF(AND(I11>=16.001,I11<=44),"S.F. BREJÃO","")&IF(AND(I11>=44.001,I11<=78),"JOÃO LISBOA","")&IF(AND(I11>=78.001,I11<=96.397),"IMPERATRIZ","")&IF(AND(I11>=96.398,I11<=122.82),"EDSON LOBÃO","")&IF(AND(I11>=122.821,I11<=152.303),"RIBAMAR FIQUENE","")&IF(AND(I11>=152.304,I11<=172.403),"CAMPESTRE","")&IF(AND(I11>=172.404,I11<=195),"PORTO FRANCO","")&IF(AND(I11>=300,I11<=300),"SAO LUIS","")&IF(AND(I11>=385.4,I11<=465.4),"Palmeirante","")&IF(AND(I11>=465.401,I11<=520.455),"Tupiratins","")&IF(AND(I11>=520.456,I11<=536.741),"Guaraí","")&IF(AND(I11>=536.742,I11<=580.293),"Tupirama","")&IF(AND(I11>=580.294,I11<=608.637),"Rio dos Bois","")&IF(AND(I11>=608.638,I11<=698.981),"Miracema","")&IF(AND(I11>=698.982,I11<=735.6),"Porto Nacional","")&IF(AND(I11>=195.1,I11<=213.603),"ESTREITO","")&IF(AND(I11>=213.604,I11<=218.976),"AGUIARNÓPOLIS","")&IF(AND(I11>=218.977,I11<=253.5),"PALMEIRAS DO TOCANTINS","")&IF(AND(I11>=253.501,I11<=274.15),"DARCINÓPOLIS","")&IF(AND(I11>=274.151,I11<=299.999),"BABAÇULÂNDIA","")&IF(AND(I11>=356.62,I11<=385.4),"ARAGUAÍNA","")&IF(AND(I11>=300.001,I11<=356.619),"BABAÇULÂNDIA","")&IF(AND(I11>=900,I11<=902),"ENG. VLI","") -> Tupirama | K11: 120 | L11: =IF(K11<>"",VLOOKUP(K11,'Catálogo SAP'!A:F,3,FALSE),"") -> S.VP-01437 | M11: =IF(K11<>"",VLOOKUP(K11,'Catálogo SAP'!A:F,4,FALSE),"") -> Hr Produtiva Retroescavadeira C/Operador | N11: =IF(K11<>"",VLOOKUP(K11,'Catálogo SAP'!A:F,5,FALSE),"") -> H | O11: 9 | P11: =IF(G11="","-",G11-F11) -> 9 | Q11: =IF(K11="","-",N11*O11) -> #VALUE! | R11: =IF(J11<>"",VLOOKUP(J11,'RESUMO DR'!$B$4:$E$253,4,FALSE),"-") -> T-03 | S11: =IF(J11<>"",VLOOKUP(J11,'RESUMO DR'!$B$4:$E$253,3,FALSE),"-") -> PALMAS
B12: 45642 | C12: CM-003 | D12: =IF(B12="","-",TEXT(B12,"ddd")) -> seg | E12: =IF(K12<>"",VLOOKUP(K12,'Catálogo SAP'!$A$1:$F$245,2,FALSE),"-") -> - | J12: =IF(AND(I12>=0.001,I12<=16),"AÇAILÂNDIA","")&IF(AND(I12>=16.001,I12<=44),"S.F. BREJÃO","")&IF(AND(I12>=44.001,I12<=78),"JOÃO LISBOA","")&IF(AND(I12>=78.001,I12<=96.397),"IMPERATRIZ","")&IF(AND(I12>=96.398,I12<=122.82),"EDSON LOBÃO","")&IF(AND(I12>=122.821,I12<=152.303),"RIBAMAR FIQUENE","")&IF(AND(I12>=152.304,I12<=172.403),"CAMPESTRE","")&IF(AND(I12>=172.404,I12<=195),"PORTO FRANCO","")&IF(AND(I12>=300,I12<=300),"SAO LUIS","")&IF(AND(I12>=385.4,I12<=465.4),"Palmeirante","")&IF(AND(I12>=465.401,I12<=520.455),"Tupiratins","")&IF(AND(I12>=520.456,I12<=536.741),"Guaraí","")&IF(AND(I12>=536.742,I12<=580.293),"Tupirama","")&IF(AND(I12>=580.294,I12<=608.637),"Rio dos Bois","")&IF(AND(I12>=608.638,I12<=698.981),"Miracema","")&IF(AND(I12>=698.982,I12<=735.6),"Porto Nacional","")&IF(AND(I12>=195.1,I12<=213.603),"ESTREITO","")&IF(AND(I12>=213.604,I12<=218.976),"AGUIARNÓPOLIS","")&IF(AND(I12>=218.977,I12<=253.5),"PALMEIRAS DO TOCANTINS","")&IF(AND(I12>=253.501,I12<=274.15),"DARCINÓPOLIS","")&IF(AND(I12>=274.151,I12<=299.999),"BABAÇULÂNDIA","")&IF(AND(I12>=356.62,I12<=385.4),"ARAGUAÍNA","")&IF(AND(I12>=300.001,I12<=356.619),"BABAÇULÂNDIA","")&IF(AND(I12>=900,I12<=902),"ENG. VLI","") | L12: =IF(K12<>"",VLOOKUP(K12,'Catálogo SAP'!A:F,3,FALSE),"") | M12: =IF(K12<>"",VLOOKUP(K12,'Catálogo SAP'!A:F,4,FALSE),"") | N12: =IF(K12<>"",VLOOKUP(K12,'Catálogo SAP'!A:F,5,FALSE),"") | P12: =IF(G12="","-",G12-F12) -> - | Q12: =IF(K12="","-",N12*O12) -> - | R12: =IF(J12<>"",VLOOKUP(J12,'RESUMO DR'!$B$4:$E$253,4,FALSE),"-") -> - | S12: =IF(J12<>"",VLOOKUP(J12,'RESUMO DR'!$B$4:$E$253,3,FALSE),"-") -> -
B13: 45642 | C13: CM-003 | D13: =IF(B13="","-",TEXT(B13,"ddd")) -> seg | E13: =IF(K13<>"",VLOOKUP(K13,'Catálogo SAP'!$A$1:$F$245,2,FALSE),"-") -> - | J13: =IF(AND(I13>=0.001,I13<=16),"AÇAILÂNDIA","")&IF(AND(I13>=16.001,I13<=44),"S.F. BREJÃO","")&IF(AND(I13>=44.001,I13<=78),"JOÃO LISBOA","")&IF(AND(I13>=78.001,I13<=96.397),"IMPERATRIZ","")&IF(AND(I13>=96.398,I13<=122.82),"EDSON LOBÃO","")&IF(AND(I13>=122.821,I13<=152.303),"RIBAMAR FIQUENE","")&IF(AND(I13>=152.304,I13<=172.403),"CAMPESTRE","")&IF(AND(I13>=172.404,I13<=195),"PORTO FRANCO","")&IF(AND(I13>=300,I13<=300),"SAO LUIS","")&IF(AND(I13>=385.4,I13<=465.4),"Palmeirante","")&IF(AND(I13>=465.401,I13<=520.455),"Tupiratins","")&IF(AND(I13>=520.456,I13<=536.741),"Guaraí","")&IF(AND(I13>=536.742,I13<=580.293),"Tupirama","")&IF(AND(I13>=580.294,I13<=608.637),"Rio dos Bois","")&IF(AND(I13>=608.638,I13<=698.981),"Miracema","")&IF(AND(I13>=698.982,I13<=735.6),"Porto Nacional","")&IF(AND(I13>=195.1,I13<=213.603),"ESTREITO","")&IF(AND(I13>=213.604,I13<=218.976),"AGUIARNÓPOLIS","")&IF(AND(I13>=218.977,I13<=253.5),"PALMEIRAS DO TOCANTINS","")&IF(AND(I13>=253.501,I13<=274.15),"DARCINÓPOLIS","")&IF(AND(I13>=274.151,I13<=299.999),"BABAÇULÂNDIA","")&IF(AND(I13>=356.62,I13<=385.4),"ARAGUAÍNA","")&IF(AND(I13>=300.001,I13<=356.619),"BABAÇULÂNDIA","")&IF(AND(I13>=900,I13<=902),"ENG. VLI","") | L13: =IF(K13<>"",VLOOKUP(K13,'Catálogo SAP'!A:F,3,FALSE),"") | M13: =IF(K13<>"",VLOOKUP(K13,'Catálogo SAP'!A:F,4,FALSE),"") | N13: =IF(K13<>"",VLOOKUP(K13,'Catálogo SAP'!A:F,5,FALSE),"") | P13: =IF(G13="","-",G13-F13) -> - | Q13: =IF(K13="","-",N13*O13) -> - | R13: =IF(J13<>"",VLOOKUP(J13,'RESUMO DR'!$B$4:$E$253,4,FALSE),"-") -> - | S13: =IF(J13<>"",VLOOKUP(J13,'RESUMO DR'!$B$4:$E$253,3,FALSE),"-") -> -
A14: 1781 | B14: 45642 | C14: EH-008 | D14: =IF(B14="","-",TEXT(B14,"ddd")) -> seg | E14: =IF(K14<>"",VLOOKUP(K14,'Catálogo SAP'!$A$1:$F$245,2,FALSE),"-") -> 520 | F14: 10507 | G14: 10515 | I14: 195 | J14: =IF(AND(I14>=0.001,I14<=16),"AÇAILÂNDIA","")&IF(AND(I14>=16.001,I14<=44),"S.F. BREJÃO","")&IF(AND(I14>=44.001,I14<=78),"JOÃO LISBOA","")&IF(AND(I14>=78.001,I14<=96.397),"IMPERATRIZ","")&IF(AND(I14>=96.398,I14<=122.82),"EDSON LOBÃO","")&IF(AND(I14>=122.821,I14<=152.303),"RIBAMAR FIQUENE","")&IF(AND(I14>=152.304,I14<=172.403),"CAMPESTRE","")&IF(AND(I14>=172.404,I14<=195),"PORTO FRANCO","")&IF(AND(I14>=300,I14<=300),"SAO LUIS","")&IF(AND(I14>=385.4,I14<=465.4),"Palmeirante","")&IF(AND(I14>=465.401,I14<=520.455),"Tupiratins","")&IF(AND(I14>=520.456,I14<=536.741),"Guaraí","")&IF(AND(I14>=536.742,I14<=580.293),"Tupirama","")&IF(AND(I14>=580.294,I14<=608.637),"Rio dos Bois","")&IF(AND(I14>=608.638,I14<=698.981),"Miracema","")&IF(AND(I14>=698.982,I14<=735.6),"Porto Nacional","")&IF(AND(I14>=195.1,I14<=213.603),"ESTREITO","")&IF(AND(I14>=213.604,I14<=218.976),"AGUIARNÓPOLIS","")&IF(AND(I14>=218.977,I14<=253.5),"PALMEIRAS DO TOCANTINS","")&IF(AND(I14>=253.501,I14<=274.15),"DARCINÓPOLIS","")&IF(AND(I14>=274.151,I14<=299.999),"BABAÇULÂNDIA","")&IF(AND(I14>=356.62,I14<=385.4),"ARAGUAÍNA","")&IF(AND(I14>=300.001,I14<=356.619),"BABAÇULÂNDIA","")&IF(AND(I14>=900,I14<=902),"ENG. VLI","") -> PORTO FRANCO | K14: 520 | L14: =IF(K14<>"",VLOOKUP(K14,'Catálogo SAP'!A:F,3,FALSE),"") -> S.VP-01469 | M14: =IF(K14<>"",VLOOKUP(K14,'Catálogo SAP'!A:F,4,FALSE),"") -> Hora Produtiva Escavadeira Hidraulica | N14: =IF(K14<>"",VLOOKUP(K14,'Catálogo SAP'!A:F,5,FALSE),"") -> H | O14: 8 | P14: =IF(G14="","-",G14-F14) -> 8 | Q14: =IF(K14="","-",N14*O14) -> #VALUE! | R14: =IF(J14<>"",VLOOKUP(J14,'RESUMO DR'!$B$4:$E$253,4,FALSE),"-") -> T-01 | S14: =IF(J14<>"",VLOOKUP(J14,'RESUMO DR'!$B$4:$E$253,3,FALSE),"-") -> IMPERATRIZ
A15: 1781 | B15: 45642 | C15: EH-008 | D15: =IF(B15="","-",TEXT(B15,"ddd")) -> seg | E15: =IF(K15<>"",VLOOKUP(K15,'Catálogo SAP'!$A$1:$F$245,2,FALSE),"-") -> 530 | F15: 10515 | G15: 10515 | I15: 195 | J15: =IF(AND(I15>=0.001,I15<=16),"AÇAILÂNDIA","")&IF(AND(I15>=16.001,I15<=44),"S.F. BREJÃO","")&IF(AND(I15>=44.001,I15<=78),"JOÃO LISBOA","")&IF(AND(I15>=78.001,I15<=96.397),"IMPERATRIZ","")&IF(AND(I15>=96.398,I15<=122.82),"EDSON LOBÃO","")&IF(AND(I15>=122.821,I15<=152.303),"RIBAMAR FIQUENE","")&IF(AND(I15>=152.304,I15<=172.403),"CAMPESTRE","")&IF(AND(I15>=172.404,I15<=195),"PORTO FRANCO","")&IF(AND(I15>=300,I15<=300),"SAO LUIS","")&IF(AND(I15>=385.4,I15<=465.4),"Palmeirante","")&IF(AND(I15>=465.401,I15<=520.455),"Tupiratins","")&IF(AND(I15>=520.456,I15<=536.741),"Guaraí","")&IF(AND(I15>=536.742,I15<=580.293),"Tupirama","")&IF(AND(I15>=580.294,I15<=608.637),"Rio dos Bois","")&IF(AND(I15>=608.638,I15<=698.981),"Miracema","")&IF(AND(I15>=698.982,I15<=735.6),"Porto Nacional","")&IF(AND(I15>=195.1,I15<=213.603),"ESTREITO","")&IF(AND(I15>=213.604,I15<=218.976),"AGUIARNÓPOLIS","")&IF(AND(I15>=218.977,I15<=253.5),"PALMEIRAS DO TOCANTINS","")&IF(AND(I15>=253.501,I15<=274.15),"DARCINÓPOLIS","")&IF(AND(I15>=274.151,I15<=299.999),"BABAÇULÂNDIA","")&IF(AND(I15>=356.62,I15<=385.4),"ARAGUAÍNA","")&IF(AND(I15>=300.001,I15<=356.619),"BABAÇULÂNDIA","")&IF(AND(I15>=900,I15<=902),"ENG. VLI","") -> PORTO FRANCO | K15: 530 | L15: =IF(K15<>"",VLOOKUP(K15,'Catálogo SAP'!A:F,3,FALSE),"") -> S.VP-01470 | M15: =IF(K15<>"",VLOOKUP(K15,'Catálogo SAP'!A:F,4,FALSE),"") -> Hora Improdutiva Escavadeira Hidraulica | N15: =IF(K15<>"",VLOOKUP(K15,'Catálogo SAP'!A:F,5,FALSE),"") -> H | O15: 1 | P15: =IF(G15="","-",G15-F15) -> 0 | Q15: =IF(K15="","-",N15*O15) -> #VALUE! | R15: =IF(J15<>"",VLOOKUP(J15,'RESUMO DR'!$B$4:$E$253,4,FALSE),"-") -> T-01 | S15: =IF(J15<>"",VLOOKUP(J15,'RESUMO DR'!$B$4:$E$253,3,FALSE),"-") -> IMPERATRIZ
A16: 1783 | B16: 45642 | C16: PC-006 | D16: =IF(B16="","-",TEXT(B16,"ddd")) -> seg | E16: =IF(K16<>"",VLOOKUP(K16,'Catálogo SAP'!$A$1:$F$245,2,FALSE),"-") -> 160 | F16: 486 | G16: 495 | I16: 126 | J16: =IF(AND(I16>=0.001,I16<=16),"AÇAILÂNDIA","")&IF(AND(I16>=16.001,I16<=44),"S.F. BREJÃO","")&IF(AND(I16>=44.001,I16<=78),"JOÃO LISBOA","")&IF(AND(I16>=78.001,I16<=96.397),"IMPERATRIZ","")&IF(AND(I16>=96.398,I16<=122.82),"EDSON LOBÃO","")&IF(AND(I16>=122.821,I16<=152.303),"RIBAMAR FIQUENE","")&IF(AND(I16>=152.304,I16<=172.403),"CAMPESTRE","")&IF(AND(I16>=172.404,I16<=195),"PORTO FRANCO","")&IF(AND(I16>=300,I16<=300),"SAO LUIS","")&IF(AND(I16>=385.4,I16<=465.4),"Palmeirante","")&IF(AND(I16>=465.401,I16<=520.455),"Tupiratins","")&IF(AND(I16>=520.456,I16<=536.741),"Guaraí","")&IF(AND(I16>=536.742,I16<=580.293),"Tupirama","")&IF(AND(I16>=580.294,I16<=608.637),"Rio dos Bois","")&IF(AND(I16>=608.638,I16<=698.981),"Miracema","")&IF(AND(I16>=698.982,I16<=735.6),"Porto Nacional","")&IF(AND(I16>=195.1,I16<=213.603),"ESTREITO","")&IF(AND(I16>=213.604,I16<=218.976),"AGUIARNÓPOLIS","")&IF(AND(I16>=218.977,I16<=253.5),"PALMEIRAS DO TOCANTINS","")&IF(AND(I16>=253.501,I16<=274.15),"DARCINÓPOLIS","")&IF(AND(I16>=274.151,I16<=299.999),"BABAÇULÂNDIA","")&IF(AND(I16>=356.62,I16<=385.4),"ARAGUAÍNA","")&IF(AND(I16>=300.001,I16<=356.619),"BABAÇULÂNDIA","")&IF(AND(I16>=900,I16<=902),"ENG. VLI","") -> RIBAMAR FIQUENE | K16: 160 | L16: =IF(K16<>"",VLOOKUP(K16,'Catálogo SAP'!A:F,3,FALSE),"") -> S.VP-01441 | M16: =IF(K16<>"",VLOOKUP(K16,'Catálogo SAP'!A:F,4,FALSE),"") -> Hora Produtiva Pa Carregadeira C/Operador | N16: =IF(K16<>"",VLOOKUP(K16,'Catálogo SAP'!A:F,5,FALSE),"") -> H | O16: 9 | P16: =IF(G16="","-",G16-F16) -> 9 | Q16: =IF(K16="","-",N16*O16) -> #VALUE! | R16: =IF(J16<>"",VLOOKUP(J16,'RESUMO DR'!$B$4:$E$253,4,FALSE),"-") -> T-01 | S16: =IF(J16<>"",VLOOKUP(J16,'RESUMO DR'!$B$4:$E$253,3,FALSE),"-") -> IMPERATRIZ
A17: 1779 | B17: 45642 | C17: CBL-052 | D17: =IF(B17="","-",TEXT(B17,"ddd")) -> seg | E17: =IF(K17<>"",VLOOKUP(K17,'Catálogo SAP'!$A$1:$F$245,2,FALSE),"-") -> 200 | F17: 63391 | G17: 63625 | I17: 163 | J17: =IF(AND(I17>=0.001,I17<=16),"AÇAILÂNDIA","")&IF(AND(I17>=16.001,I17<=44),"S.F. BREJÃO","")&IF(AND(I17>=44.001,I17<=78),"JOÃO LISBOA","")&IF(AND(I17>=78.001,I17<=96.397),"IMPERATRIZ","")&IF(AND(I17>=96.398,I17<=122.82),"EDSON LOBÃO","")&IF(AND(I17>=122.821,I17<=152.303),"RIBAMAR FIQUENE","")&IF(AND(I17>=152.304,I17<=172.403),"CAMPESTRE","")&IF(AND(I17>=172.404,I17<=195),"PORTO FRANCO","")&IF(AND(I17>=300,I17<=300),"SAO LUIS","")&IF(AND(I17>=385.4,I17<=465.4),"Palmeirante","")&IF(AND(I17>=465.401,I17<=520.455),"Tupiratins","")&IF(AND(I17>=520.456,I17<=536.741),"Guaraí","")&IF(AND(I17>=536.742,I17<=580.293),"Tupirama","")&IF(AND(I17>=580.294,I17<=608.637),"Rio dos Bois","")&IF(AND(I17>=608.638,I17<=698.981),"Miracema","")&IF(AND(I17>=698.982,I17<=735.6),"Porto Nacional","")&IF(AND(I17>=195.1,I17<=213.603),"ESTREITO","")&IF(AND(I17>=213.604,I17<=218.976),"AGUIARNÓPOLIS","")&IF(AND(I17>=218.977,I17<=253.5),"PALMEIRAS DO TOCANTINS","")&IF(AND(I17>=253.501,I17<=274.15),"DARCINÓPOLIS","")&IF(AND(I17>=274.151,I17<=299.999),"BABAÇULÂNDIA","")&IF(AND(I17>=356.62,I17<=385.4),"ARAGUAÍNA","")&IF(AND(I17>=300.001,I17<=356.619),"BABAÇULÂNDIA","")&IF(AND(I17>=900,I17<=902),"ENG. VLI","") -> CAMPESTRE | K17: 200 | L17: =IF(K17<>"",VLOOKUP(K17,'Catálogo SAP'!A:F,3,FALSE),"") -> S.VP-01445 | M17: =IF(K17<>"",VLOOKUP(K17,'Catálogo SAP'!A:F,4,FALSE),"") -> Km Rodado Caminhão Basculante - C/Motorista | N17: =IF(K17<>"",VLOOKUP(K17,'Catálogo SAP'!A:F,5,FALSE),"") -> KM | O17: 234 | P17: =IF(G17="","-",G17-F17) -> 234 | Q17: =IF(K17="","-",N17*O17) -> #VALUE! | R17: =IF(J17<>"",VLOOKUP(J17,'RESUMO DR'!$B$4:$E$253,4,FALSE),"-") -> T-01 | S17: =IF(J17<>"",VLOOKUP(J17,'RESUMO DR'!$B$4:$E$253,3,FALSE),"-") -> IMPERATRIZ
A18: 1779 | B18: 45642 | C18: CBL-051 | D18: =IF(B18="","-",TEXT(B18,"ddd")) -> seg | E18: =IF(K18<>"",VLOOKUP(K18,'Catálogo SAP'!$A$1:$F$245,2,FALSE),"-") -> 200 | F18: 59575 | G18: 59889 | I18: 163 | J18: =IF(AND(I18>=0.001,I18<=16),"AÇAILÂNDIA","")&IF(AND(I18>=16.001,I18<=44),"S.F. BREJÃO","")&IF(AND(I18>=44.001,I18<=78),"JOÃO LISBOA","")&IF(AND(I18>=78.001,I18<=96.397),"IMPERATRIZ","")&IF(AND(I18>=96.398,I18<=122.82),"EDSON LOBÃO","")&IF(AND(I18>=122.821,I18<=152.303),"RIBAMAR FIQUENE","")&IF(AND(I18>=152.304,I18<=172.403),"CAMPESTRE","")&IF(AND(I18>=172.404,I18<=195),"PORTO FRANCO","")&IF(AND(I18>=300,I18<=300),"SAO LUIS","")&IF(AND(I18>=385.4,I18<=465.4),"Palmeirante","")&IF(AND(I18>=465.401,I18<=520.455),"Tupiratins","")&IF(AND(I18>=520.456,I18<=536.741),"Guaraí","")&IF(AND(I18>=536.742,I18<=580.293),"Tupirama","")&IF(AND(I18>=580.294,I18<=608.637),"Rio dos Bois","")&IF(AND(I18>=608.638,I18<=698.981),"Miracema","")&IF(AND(I18>=698.982,I18<=735.6),"Porto Nacional","")&IF(AND(I18>=195.1,I18<=213.603),"ESTREITO","")&IF(AND(I18>=213.604,I18<=218.976),"AGUIARNÓPOLIS","")&IF(AND(I18>=218.977,I18<=253.5),"PALMEIRAS DO TOCANTINS","")&IF(AND(I18>=253.501,I18<=274.15),"DARCINÓPOLIS","")&IF(AND(I18>=274.151,I18<=299.999),"BABAÇULÂNDIA","")&IF(AND(I18>=356.62,I18<=385.4),"ARAGUAÍNA","")&IF(AND(I18>=300.001,I18<=356.619),"BABAÇULÂNDIA","")&IF(AND(I18>=900,I18<=902),"ENG. VLI","") -> CAMPESTRE | K18: 200 | L18: =IF(K18<>"",VLOOKUP(K18,'Catálogo SAP'!A:F,3,FALSE),"") -> S.VP-01445 | M18: =IF(K18<>"",VLOOKUP(K18,'Catálogo SAP'!A:F,4,FALSE),"") -> Km Rodado Caminhão Basculante - C/Motorista | N18: =IF(K18<>"",VLOOKUP(K18,'Catálogo SAP'!A:F,5,FALSE),"") -> KM | O18: 314 | P18: =IF(G18="","-",G18-F18) -> 314 | Q18: =IF(K18="","-",N18*O18) -> #VALUE! | R18: =IF(J18<>"",VLOOKUP(J18,'RESUMO DR'!$B$4:$E$253,4,FALSE),"-") -> T-01 | S18: =IF(J18<>"",VLOOKUP(J18,'RESUMO DR'!$B$4:$E$253,3,FALSE),"-") -> IMPERATRIZ
A19: 1789 | B19: 45642 | C19: CBL-003 | D19: =IF(B19="","-",TEXT(B19,"ddd")) -> seg | E19: =IF(K19<>"",VLOOKUP(K19,'Catálogo SAP'!$A$1:$F$245,2,FALSE),"-") -> 200 | F19: 47550 | G19: 47615 | I19: 442 | J19: =IF(AND(I19>=0.001,I19<=16),"AÇAILÂNDIA","")&IF(AND(I19>=16.001,I19<=44),"S.F. BREJÃO","")&IF(AND(I19>=44.001,I19<=78),"JOÃO LISBOA","")&IF(AND(I19>=78.001,I19<=96.397),"IMPERATRIZ","")&IF(AND(I19>=96.398,I19<=122.82),"EDSON LOBÃO","")&IF(AND(I19>=122.821,I19<=152.303),"RIBAMAR FIQUENE","")&IF(AND(I19>=152.304,I19<=172.403),"CAMPESTRE","")&IF(AND(I19>=172.404,I19<=195),"PORTO FRANCO","")&IF(AND(I19>=300,I19<=300),"SAO LUIS","")&IF(AND(I19>=385.4,I19<=465.4),"Palmeirante","")&IF(AND(I19>=465.401,I19<=520.455),"Tupiratins","")&IF(AND(I19>=520.456,I19<=536.741),"Guaraí","")&IF(AND(I19>=536.742,I19<=580.293),"Tupirama","")&IF(AND(I19>=580.294,I19<=608.637),"Rio dos Bois","")&IF(AND(I19>=608.638,I19<=698.981),"Miracema","")&IF(AND(I19>=698.982,I19<=735.6),"Porto Nacional","")&IF(AND(I19>=195.1,I19<=213.603),"ESTREITO","")&IF(AND(I19>=213.604,I19<=218.976),"AGUIARNÓPOLIS","")&IF(AND(I19>=218.977,I19<=253.5),"PALMEIRAS DO TOCANTINS","")&IF(AND(I19>=253.501,I19<=274.15),"DARCINÓPOLIS","")&IF(AND(I19>=274.151,I19<=299.999),"BABAÇULÂNDIA","")&IF(AND(I19>=356.62,I19<=385.4),"ARAGUAÍNA","")&IF(AND(I19>=300.001,I19<=356.619),"BABAÇULÂNDIA","")&IF(AND(I19>=900,I19<=902),"ENG. VLI","") -> Palmeirante | K19: 200 | L19: =IF(K19<>"",VLOOKUP(K19,'Catálogo SAP'!A:F,3,FALSE),"") -> S.VP-01445 | M19: =IF(K19<>"",VLOOKUP(K19,'Catálogo SAP'!A:F,4,FALSE),"") -> Km Rodado Caminhão Basculante - C/Motorista | N19: =IF(K19<>"",VLOOKUP(K19,'Catálogo SAP'!A:F,5,FALSE),"") -> KM | O19: 65 | P19: =IF(G19="","-",G19-F19) -> 65 | Q19: =IF(K19="","-",N19*O19) -> #VALUE! | R19: =IF(J19<>"",VLOOKUP(J19,'RESUMO DR'!$B$4:$E$253,4,FALSE),"-") -> T-02 | S19: =IF(J19<>"",VLOOKUP(J19,'RESUMO DR'!$B$4:$E$253,3,FALSE),"-") -> ARAGUAINA
A20: 1783 | B20: 45642 | C20: CBL-054 | D20: =IF(B20="","-",TEXT(B20,"ddd")) -> seg | E20: =IF(K20<>"",VLOOKUP(K20,'Catálogo SAP'!$A$1:$F$245,2,FALSE),"-") -> 200 | F20: 62596 | G20: 63020 | I20: 126 | J20: =IF(AND(I20>=0.001,I20<=16),"AÇAILÂNDIA","")&IF(AND(I20>=16.001,I20<=44),"S.F. BREJÃO","")&IF(AND(I20>=44.001,I20<=78),"JOÃO LISBOA","")&IF(AND(I20>=78.001,I20<=96.397),"IMPERATRIZ","")&IF(AND(I20>=96.398,I20<=122.82),"EDSON LOBÃO","")&IF(AND(I20>=122.821,I20<=152.303),"RIBAMAR FIQUENE","")&IF(AND(I20>=152.304,I20<=172.403),"CAMPESTRE","")&IF(AND(I20>=172.404,I20<=195),"PORTO FRANCO","")&IF(AND(I20>=300,I20<=300),"SAO LUIS","")&IF(AND(I20>=385.4,I20<=465.4),"Palmeirante","")&IF(AND(I20>=465.401,I20<=520.455),"Tupiratins","")&IF(AND(I20>=520.456,I20<=536.741),"Guaraí","")&IF(AND(I20>=536.742,I20<=580.293),"Tupirama","")&IF(AND(I20>=580.294,I20<=608.637),"Rio dos Bois","")&IF(AND(I20>=608.638,I20<=698.981),"Miracema","")&IF(AND(I20>=698.982,I20<=735.6),"Porto Nacional","")&IF(AND(I20>=195.1,I20<=213.603),"ESTREITO","")&IF(AND(I20>=213.604,I20<=218.976),"AGUIARNÓPOLIS","")&IF(AND(I20>=218.977,I20<=253.5),"PALMEIRAS DO TOCANTINS","")&IF(AND(I20>=253.501,I20<=274.15),"DARCINÓPOLIS","")&IF(AND(I20>=274.151,I20<=299.999),"BABAÇULÂNDIA","")&IF(AND(I20>=356.62,I20<=385.4),"ARAGUAÍNA","")&IF(AND(I20>=300.001,I20<=356.619),"BABAÇULÂNDIA","")&IF(AND(I20>=900,I20<=902),"ENG. VLI","") -> RIBAMAR FIQUENE | K20: 200 | L20: =IF(K20<>"",VLOOKUP(K20,'Catálogo SAP'!A:F,3,FALSE),"") -> S.VP-01445 | M20: =IF(K20<>"",VLOOKUP(K20,'Catálogo SAP'!A:F,4,FALSE),"") -> Km Rodado Caminhão Basculante - C/Motorista | N20: =IF(K20<>"",VLOOKUP(K20,'Catálogo SAP'!A:F,5,FALSE),"") -> KM | O20: 424 | P20: =IF(G20="","-",G20-F20) -> 424 | Q20: =IF(K20="","-",N20*O20) -> #VALUE! | R20: =IF(J20<>"",VLOOKUP(J20,'RESUMO DR'!$B$4:$E$253,4,FALSE),"-") -> T-01 | S20: =IF(J20<>"",VLOOKUP(J20,'RESUMO DR'!$B$4:$E$253,3,FALSE),"-") -> IMPERATRIZ
A21: 1783 | B21: 45642 | C21: CBL-055 | D21: =IF(B21="","-",TEXT(B21,"ddd")) -> seg | E21: =IF(K21<>"",VLOOKUP(K21,'Catálogo SAP'!$A$1:$F$245,2,FALSE),"-") -> 200 | F21: 62701 | G21: 63142 | I21: 126 | J21: =IF(AND(I21>=0.001,I21<=16),"AÇAILÂNDIA","")&IF(AND(I21>=16.001,I21<=44),"S.F. BREJÃO","")&IF(AND(I21>=44.001,I21<=78),"JOÃO LISBOA","")&IF(AND(I21>=78.001,I21<=96.397),"IMPERATRIZ","")&IF(AND(I21>=96.398,I21<=122.82),"EDSON LOBÃO","")&IF(AND(I21>=122.821,I21<=152.303),"RIBAMAR FIQUENE","")&IF(AND(I21>=152.304,I21<=172.403),"CAMPESTRE","")&IF(AND(I21>=172.404,I21<=195),"PORTO FRANCO","")&IF(AND(I21>=300,I21<=300),"SAO LUIS","")&IF(AND(I21>=385.4,I21<=465.4),"Palmeirante","")&IF(AND(I21>=465.401,I21<=520.455),"Tupiratins","")&IF(AND(I21>=520.456,I21<=536.741),"Guaraí","")&IF(AND(I21>=536.742,I21<=580.293),"Tupirama","")&IF(AND(I21>=580.294,I21<=608.637),"Rio dos Bois","")&IF(AND(I21>=608.638,I21<=698.981),"Miracema","")&IF(AND(I21>=698.982,I21<=735.6),"Porto Nacional","")&IF(AND(I21>=195.1,I21<=213.603),"ESTREITO","")&IF(AND(I21>=213.604,I21<=218.976),"AGUIARNÓPOLIS","")&IF(AND(I21>=218.977,I21<=253.5),"PALMEIRAS DO TOCANTINS","")&IF(AND(I21>=253.501,I21<=274.15),"DARCINÓPOLIS","")&IF(AND(I21>=274.151,I21<=299.999),"BABAÇULÂNDIA","")&IF(AND(I21>=356.62,I21<=385.4),"ARAGUAÍNA","")&IF(AND(I21>=300.001,I21<=356.619),"BABAÇULÂNDIA","")&IF(AND(I21>=900,I21<=902),"ENG. VLI","") -> RIBAMAR FIQUENE | K21: 200 | L21: =IF(K21<>"",VLOOKUP(K21,'Catálogo SAP'!A:F,3,FALSE),"") -> S.VP-01445 | M21: =IF(K21<>"",VLOOKUP(K21,'Catálogo SAP'!A:F,4,FALSE),"") -> Km Rodado Caminhão Basculante - C/Motorista | N21: =IF(K21<>"",VLOOKUP(K21,'Catálogo SAP'!A:F,5,FALSE),"") -> KM | O21: 441 | P21: =IF(G21="","-",G21-F21) -> 441 | Q21: =IF(K21="","-",N21*O21) -> #VALUE! | R21: =IF(J21<>"",VLOOKUP(J21,'RESUMO DR'!$B$4:$E$253,4,FALSE),"-") -> T-01 | S21: =IF(J21<>"",VLOOKUP(J21,'RESUMO DR'!$B$4:$E$253,3,FALSE),"-") -> IMPERATRIZ
A22: 1785 | B22: 45642 | C22: CBL-005 | D22: =IF(B22="","-",TEXT(B22,"ddd")) -> seg | E22: =IF(K22<>"",VLOOKUP(K22,'Catálogo SAP'!$A$1:$F$245,2,FALSE),"-") -> 200 | F22: 79882 | G22: 80027 | I22: 577 | J22: =IF(AND(I22>=0.001,I22<=16),"AÇAILÂNDIA","")&IF(AND(I22>=16.001,I22<=44),"S.F. BREJÃO","")&IF(AND(I22>=44.001,I22<=78),"JOÃO LISBOA","")&IF(AND(I22>=78.001,I22<=96.397),"IMPERATRIZ","")&IF(AND(I22>=96.398,I22<=122.82),"EDSON LOBÃO","")&IF(AND(I22>=122.821,I22<=152.303),"RIBAMAR FIQUENE","")&IF(AND(I22>=152.304,I22<=172.403),"CAMPESTRE","")&IF(AND(I22>=172.404,I22<=195),"PORTO FRANCO","")&IF(AND(I22>=300,I22<=300),"SAO LUIS","")&IF(AND(I22>=385.4,I22<=465.4),"Palmeirante","")&IF(AND(I22>=465.401,I22<=520.455),"Tupiratins","")&IF(AND(I22>=520.456,I22<=536.741),"Guaraí","")&IF(AND(I22>=536.742,I22<=580.293),"Tupirama","")&IF(AND(I22>=580.294,I22<=608.637),"Rio dos Bois","")&IF(AND(I22>=608.638,I22<=698.981),"Miracema","")&IF(AND(I22>=698.982,I22<=735.6),"Porto Nacional","")&IF(AND(I22>=195.1,I22<=213.603),"ESTREITO","")&IF(AND(I22>=213.604,I22<=218.976),"AGUIARNÓPOLIS","")&IF(AND(I22>=218.977,I22<=253.5),"PALMEIRAS DO TOCANTINS","")&IF(AND(I22>=253.501,I22<=274.15),"DARCINÓPOLIS","")&IF(AND(I22>=274.151,I22<=299.999),"BABAÇULÂNDIA","")&IF(AND(I22>=356.62,I22<=385.4),"ARAGUAÍNA","")&IF(AND(I22>=300.001,I22<=356.619),"BABAÇULÂNDIA","")&IF(AND(I22>=900,I22<=902),"ENG. VLI","") -> Tupirama | K22: 200 | L22: =IF(K22<>"",VLOOKUP(K22,'Catálogo SAP'!A:F,3,FALSE),"") -> S.VP-01445 | M22: =IF(K22<>"",VLOOKUP(K22,'Catálogo SAP'!A:F,4,FALSE),"") -> Km Rodado Caminhão Basculante - C/Motorista | N22: =IF(K22<>"",VLOOKUP(K22,'Catálogo SAP'!A:F,5,FALSE),"") -> KM | O22: 145 | P22: =IF(G22="","-",G22-F22) -> 145 | Q22: =IF(K22="","-",N22*O22) -> #VALUE! | R22: =IF(J22<>"",VLOOKUP(J22,'RESUMO DR'!$B$4:$E$253,4,FALSE),"-") -> T-03 | S22: =IF(J22<>"",VLOOKUP(J22,'RESUMO DR'!$B$4:$E$253,3,FALSE),"-") -> PALMAS
A23: 1783 | B23: 45642 | C23: PCL-002 | D23: =IF(B23="","-",TEXT(B23,"ddd")) -> seg | E23: =IF(K23<>"",VLOOKUP(K23,'Catálogo SAP'!$A$1:$F$245,2,FALSE),"-") -> 170 | F23: 1335 | G23: 1335 | I23: 142 | J23: =IF(AND(I23>=0.001,I23<=16),"AÇAILÂNDIA","")&IF(AND(I23>=16.001,I23<=44),"S.F. BREJÃO","")&IF(AND(I23>=44.001,I23<=78),"JOÃO LISBOA","")&IF(AND(I23>=78.001,I23<=96.397),"IMPERATRIZ","")&IF(AND(I23>=96.398,I23<=122.82),"EDSON LOBÃO","")&IF(AND(I23>=122.821,I23<=152.303),"RIBAMAR FIQUENE","")&IF(AND(I23>=152.304,I23<=172.403),"CAMPESTRE","")&IF(AND(I23>=172.404,I23<=195),"PORTO FRANCO","")&IF(AND(I23>=300,I23<=300),"SAO LUIS","")&IF(AND(I23>=385.4,I23<=465.4),"Palmeirante","")&IF(AND(I23>=465.401,I23<=520.455),"Tupiratins","")&IF(AND(I23>=520.456,I23<=536.741),"Guaraí","")&IF(AND(I23>=536.742,I23<=580.293),"Tupirama","")&IF(AND(I23>=580.294,I23<=608.637),"Rio dos Bois","")&IF(AND(I23>=608.638,I23<=698.981),"Miracema","")&IF(AND(I23>=698.982,I23<=735.6),"Porto Nacional","")&IF(AND(I23>=195.1,I23<=213.603),"ESTREITO","")&IF(AND(I23>=213.604,I23<=218.976),"AGUIARNÓPOLIS","")&IF(AND(I23>=218.977,I23<=253.5),"PALMEIRAS DO TOCANTINS","")&IF(AND(I23>=253.501,I23<=274.15),"DARCINÓPOLIS","")&IF(AND(I23>=274.151,I23<=299.999),"BABAÇULÂNDIA","")&IF(AND(I23>=356.62,I23<=385.4),"ARAGUAÍNA","")&IF(AND(I23>=300.001,I23<=356.619),"BABAÇULÂNDIA","")&IF(AND(I23>=900,I23<=902),"ENG. VLI","") -> RIBAMAR FIQUENE | K23: 170 | L23: =IF(K23<>"",VLOOKUP(K23,'Catálogo SAP'!A:F,3,FALSE),"") -> S.VP-01442 | M23: =IF(K23<>"",VLOOKUP(K23,'Catálogo SAP'!A:F,4,FALSE),"") -> Hora Improdutiva Pa Carregadeira C/Operador | N23: =IF(K23<>"",VLOOKUP(K23,'Catálogo SAP'!A:F,5,FALSE),"") -> H | O23: 9 | P23: =IF(G23="","-",G23-F23) -> 0 | Q23: =IF(K23="","-",N23*O23) -> #VALUE! | R23: =IF(J23<>"",VLOOKUP(J23,'RESUMO DR'!$B$4:$E$253,4,FALSE),"-") -> T-01 | S23: =IF(J23<>"",VLOOKUP(J23,'RESUMO DR'!$B$4:$E$253,3,FALSE),"-") -> IMPERATRIZ
